<?xml version="1.0" ?>
<robot name="iris">
  <link name="lidar_link">
    <origin rpy="0 0 0" xyz="0.1 0 0.2"/>
    <inertial>
      <mass value="0.0001"/>
      <inertia ixx="0.00001" ixy="0" ixz="0" iyy="0.00001" iyz="0" izz="0.00001"/>
    </inertial>
    <visual>
      <geometry>
        <box size="0.02 0.02 0.02"/>
      </geometry>
      <material name="Gazebo/Red"/>
    </visual>
  </link>
  <joint name="front_camera_joint" type="fixed">
    <parent link="base_link"/>
    <child link="lidar_link"/>
     <!-- <origin rpy="-1.5708 0 0"/> -->
  </joint>
  <link name="base_link">
    <inertial>
      <origin rpy="0 0 0" xyz="0 0 0"/>
      <mass value="1.5"/>
      <inertia ixx="0.008" ixy="0" ixz="0" iyy="0.015" iyz="0" izz="0.017"/>
    </inertial>
    <visual>
      <geometry>
        <mesh filename="file:///home/hgg/Fast-Drone-250/src/ardupilot_gazebo_roscam/src/ardupilot_gazebo/models/iris_with_standoffs/meshes/iris.dae"/>
      </geometry>
      <material name="Gazebo/DarkGrey"/>
    </visual>
    <visual>
      <origin rpy="0 0 0" xyz="0.123 0.22 -0.11"/>
      <geometry>
        <cylinder length="0.17" radius="0.005"/>
      </geometry>
      <material name="Gazebo/FlatBlack"/>
    </visual>
    <visual>
      <origin rpy="0 0 0" xyz="0.123 -0.22 -0.11"/>
      <geometry>
        <cylinder length="0.17" radius="0.005"/>
      </geometry>
      <material name="Gazebo/FlatBlack"/>
    </visual>
    <visual>
      <origin rpy="0 0 0" xyz="-0.140 0.21 -0.11"/>
      <geometry>
        <cylinder length="0.17" radius="0.005"/>
      </geometry>
      <material name="Gazebo/FlatBlack"/>
    </visual>
    <visual>
      <origin rpy="0 0 0" xyz="-0.140 -0.21 -0.11"/>
      <geometry>
        <cylinder length="0.17" radius="0.005"/>
      </geometry>
      <material name="Gazebo/FlatBlack"/>
    </visual>
  </link>
  <link name="iris/ground_truth/odometry_sensorgt_link">
    <origin rpy="0 -0 0" xyz="0 0 0"/>
    <inertial>
      <origin rpy="0 -0 0" xyz="0 0 0"/>
      <mass value="0.15"/>
      <inertia ixx="0.0001" ixy="0" ixz="0" iyy="0.0002" iyz="0" izz="0.0002"/>
    </inertial>
  </link>
  <joint name="iris/ground_truth/odometry_sensorgt_joint" type="revolute">
    <child link="iris/ground_truth/odometry_sensorgt_link"/>
    <parent link="base_link"/>
    <axis xyz="0 0 1"/>
    <limit effort="0" lower="0" upper="0" velocity="0"/>
    <dynamics damping="1.0"/>
    <origin xyz="0 0 1"/>
  </joint>
  <link name="iris/imu_link">
    <inertial>
      <origin rpy="0 0 0" xyz="0 0 0"/>
      <mass value="0.15"/>
      <inertia ixx="0.00001" ixy="0" ixz="0" iyy="0.00002" iyz="0" izz="0.00002"/>
    </inertial>
  </link>
  <joint name="iris/imu_joint" type="revolute">
    <child link="iris/imu_link"/>
    <parent link="base_link"/>
    <axis xyz="0 0 1"/>
    <limit effort="0" lower="0" upper="0" velocity="0"/>
    <dynamics damping="1.0"/>
    <origin xyz="0 0 1"/>
  </joint>
  <link name="rotor_0">
    <origin rpy="0 -0 0" xyz="0.13 -0.22 0.023"/>
    <inertial>
      <origin rpy="0 -0 0" xyz="0 0 0"/>
      <mass value="0.025"/>
      <inertia ixx="9.75e-06" ixy="0" ixz="0" iyy="0.000166704" iyz="0" izz="0.000167604"/>
    </inertial>
    <visual>
      <origin rpy="0 -0 0" xyz="0 0 0"/>
      <geometry>
        <mesh filename="file:///home/hgg/Fast-Drone-250/src/ardupilot_gazebo_roscam/src/ardupilot_gazebo/models/iris_with_standoffs/meshes/iris_prop_ccw.dae" scale="1 1 1"/>
      </geometry>
      <material name="Gazebo/Blue"/>
    </visual>
  </link>
  <joint name="rotor_0_joint" type="revolute">
    <child link="rotor_0"/>
    <parent link="base_link"/>
    <axis xyz="0 0 1"/>
    <limit effort="100.0" lower="-100" upper="100" velocity="1000.0"/>
    <dynamics damping="0.004"/>
    <origin xyz="0 0 1"/>
  </joint>
  <link name="rotor_1">
    <origin rpy="0 -0 0" xyz="-0.13 0.2 0.023"/>
    <inertial>
      <origin rpy="0 -0 0" xyz="0 0 0"/>
      <mass value="0.025"/>
      <inertia ixx="9.75e-06" ixy="0" ixz="0" iyy="0.000166704" iyz="0" izz="0.000167604"/>
    </inertial>
    <visual>
      <origin rpy="0 -0 0" xyz="0 0 0"/>
      <geometry>
        <mesh filename="file:///home/hgg/Fast-Drone-250/src/ardupilot_gazebo_roscam/src/ardupilot_gazebo/models/iris_with_standoffs/meshes/iris_prop_ccw.dae" scale="1 1 1"/>
      </geometry>
      <material name="Gazebo/DarkGrey"/>
    </visual>
  </link>
  <joint name="rotor_1_joint" type="revolute">
    <child link="rotor_1"/>
    <parent link="base_link"/>
    <axis xyz="0 0 1"/>
    <limit effort="100.0" lower="-100" upper="100" velocity="1000.0"/>
    <dynamics damping="0.004"/>
    <origin xyz="0 0 1"/>
  </joint>
  <link name="rotor_2">
    <origin rpy="0 -0 0" xyz="0.13 0.22 0.023"/>
    <inertial>
      <origin rpy="0 -0 0" xyz="0 0 0"/>
      <mass value="0.025"/>
      <inertia ixx="9.75e-06" ixy="0" ixz="0" iyy="0.000166704" iyz="0" izz="0.000167604"/>
    </inertial>
    <visual>
      <origin rpy="0 -0 0" xyz="0 0 0"/>
      <geometry>
        <mesh filename="file:///home/hgg/Fast-Drone-250/src/ardupilot_gazebo_roscam/src/ardupilot_gazebo/models/iris_with_standoffs/meshes/iris_prop_cw.dae" scale="1 1 1"/>
      </geometry>
      <material name="Gazebo/Blue"/>
    </visual>
  </link>
  <joint name="rotor_2_joint" type="revolute">
    <child link="rotor_2"/>
    <parent link="base_link"/>
    <axis xyz="0 0 1"/>
    <limit effort="100.0" lower="-100" upper="100" velocity="1000.0"/>
    <dynamics damping="0.004"/>
    <origin xyz="0 0 1"/>
  </joint>
  <link name="rotor_3">
    <origin rpy="0 -0 0" xyz="-0.13 -0.2 0.023"/>
    <inertial>
      <origin rpy="0 -0 0" xyz="0 0 0"/>
      <mass value="0.025"/>
      <inertia ixx="9.75e-06" ixy="0" ixz="0" iyy="0.000166704" iyz="0" izz="0.000167604"/>
    </inertial>
    <visual>
      <origin rpy="0 -0 0" xyz="0 0 0"/>
      <geometry>
        <mesh filename="file:///home/hgg/Fast-Drone-250/src/ardupilot_gazebo_roscam/src/ardupilot_gazebo/models/iris_with_standoffs/meshes/iris_prop_cw.dae" scale="1 1 1"/>
      </geometry>
      <material name="Gazebo/DarkGrey"/>
    </visual>
  </link>
  <joint name="rotor_3_joint" type="revolute">
    <child link="rotor_3"/>
    <parent link="base_link"/>
    <axis xyz="0 0 1"/>
    <limit effort="100.0" lower="-100" upper="100" velocity="1000.0"/>
    <dynamics damping="0.004"/>
    <origin xyz="0 0 1"/>
  </joint>
  <material name="Gazebo/Red">
    <color rgba="1 0 0 1.0"/>
  </material>
  <material name="Gazebo/DarkGrey">
    <color rgba=".175 .175 .175 1.0"/>
  </material>
  <material name="Gazebo/FlatBlack">
    <color rgba="0.1 0.1 0.1 1.0"/>
  </material>
  <material name="Gazebo/Blue">
    <color rgba="0 0 1 1.0"/>
  </material>
</robot>
